Workbook

Sheet Cover Page
B3: Company: | C3: Tryonic AI Platform
B4: Project: | C4: POD T-Shirt Platform
B5: Document: | C5: Test Case Execution Summary v30
B6: Version: | C6: v30 — Source Code Sync 2026-03-26
B7: Date: | C7: 2026-03-26
B8: Structure: | C8: 9 Feature Sheets (Merged)
B9: Changes: | C9: v30: NEW: Profile Page (avatar, contact, stats, address mgmt), AddressPicker (multi-address CRUD max 5), CheckoutModal (3-step drawer). UPD: Checkout Page (AddressPicker integration, flash discount, promo codes), TopBar (/profile link), OrderModal (selectedSize)

Sheet Execution Summary
A1: Execution Summary — Test Progress Dashboard v30
A3: Feature | B3: Total TCs | C3: Pass | D3: Fail | E3: Untested | F3: N/A | G3: % Progress | H3: % Pass Rate
A4: HOME | B4: 53 | C4: =COUNTIF(HOME!O3:O59,"Pass") -> 0 | D4: =COUNTIF(HOME!O3:O59,"Fail") -> 0 | E4: =COUNTIF(HOME!O3:O59,"Untested") -> 53 | F4: =COUNTIF(HOME!O3:O59,"N/A") -> 0 | G4: =IF(B4=0,0,(B4-E4-F4)/B4) -> 0 | H4: =IF((B4-E4-F4)=0,0,C4/(B4-E4-F4)) -> 0
A5: DESIGN STUDIO | B5: 204 | C5: =COUNTIF('DESIGN STUDIO'!O3:O209,"Pass") -> 0 | D5: =COUNTIF('DESIGN STUDIO'!O3:O209,"Fail") -> 0 | E5: =COUNTIF('DESIGN STUDIO'!O3:O209,"Untested") -> 204 | F5: =COUNTIF('DESIGN STUDIO'!O3:O209,"N/A") -> 0 | G5: =IF(B5=0,0,(B5-E5-F5)/B5) -> 0 | H5: =IF((B5-E5-F5)=0,0,C5/(B5-E5-F5)) -> 0
A6: AI GENERATE | B6: 38 | C6: =COUNTIF('AI GENERATE'!O3:O44,"Pass") -> 0 | D6: =COUNTIF('AI GENERATE'!O3:O44,"Fail") -> 0 | E6: =COUNTIF('AI GENERATE'!O3:O44,"Untested") -> 38 | F6: =COUNTIF('AI GENERATE'!O3:O44,"N/A") -> 0 | G6: =IF(B6=0,0,(B6-E6-F6)/B6) -> 0 | H6: =IF((B6-E6-F6)=0,0,C6/(B6-E6-F6)) -> 0
A7: ĐẶT HÀNG | B7: 77 | C7: =COUNTIF('ĐẶT HÀNG'!O3:O81,"Pass") -> 0 | D7: =COUNTIF('ĐẶT HÀNG'!O3:O81,"Fail") -> 0 | E7: =COUNTIF('ĐẶT HÀNG'!O3:O81,"Untested") -> 77 | F7: =COUNTIF('ĐẶT HÀNG'!O3:O81,"N/A") -> 0 | G7: =IF(B7=0,0,(B7-E7-F7)/B7) -> 0 | H7: =IF((B7-E7-F7)=0,0,C7/(B7-E7-F7)) -> 0
A8: THANH TOÁN | B8: 65 | C8: =COUNTIF('THANH TOÁN'!O3:O69,"Pass") -> 0 | D8: =COUNTIF('THANH TOÁN'!O3:O69,"Fail") -> 0 | E8: =COUNTIF('THANH TOÁN'!O3:O69,"Untested") -> 65 | F8: =COUNTIF('THANH TOÁN'!O3:O69,"N/A") -> 0 | G8: =IF(B8=0,0,(B8-E8-F8)/B8) -> 0 | H8: =IF((B8-E8-F8)=0,0,C8/(B8-E8-F8)) -> 0
A9: LOGIN | B9: 120 | C9: =COUNTIF(LOGIN!O3:O125,"Pass") -> 0 | D9: =COUNTIF(LOGIN!O3:O125,"Fail") -> 0 | E9: =COUNTIF(LOGIN!O3:O125,"Untested") -> 120 | F9: =COUNTIF(LOGIN!O3:O125,"N/A") -> 0 | G9: =IF(B9=0,0,(B9-E9-F9)/B9) -> 0 | H9: =IF((B9-E9-F9)=0,0,C9/(B9-E9-F9)) -> 0
A10: E2E FLOW | B10: 6 | C10: =COUNTIF('[1]E2E FLOW'!O3:O8,"Pass") -> #VALUE! | D10: =COUNTIF('[1]E2E FLOW'!O3:O8,"Fail") -> #VALUE! | E10: =COUNTIF('[1]E2E FLOW'!O3:O8,"Untested") -> #VALUE! | F10: =COUNTIF('[1]E2E FLOW'!O3:O8,"N/A") -> #VALUE! | G10: =IF(B10=0,0,(B10-E10-F10)/B10) -> #VALUE! | H10: =IF((B10-E10-F10)=0,0,C10/(B10-E10-F10)) -> #VALUE!
A11: MY ORDERS | B11: 25 | C11: =COUNTIF('MY ORDERS'!O3:O29,"Pass") -> 0 | D11: =COUNTIF('MY ORDERS'!O3:O29,"Fail") -> 0 | E11: =COUNTIF('MY ORDERS'!O3:O29,"Untested") -> 25 | F11: =COUNTIF('MY ORDERS'!O3:O29,"N/A") -> 0 | G11: =IF(B11=0,0,(B11-E11-F11)/B11) -> 0 | H11: =IF((B11-E11-F11)=0,0,C11/(B11-E11-F11)) -> 0
A12: POLICY PAGES | B12: 10 | C12: =COUNTIF('POLICY PAGES'!O3:O14,"Pass") -> 0 | D12: =COUNTIF('POLICY PAGES'!O3:O14,"Fail") -> 0 | E12: =COUNTIF('POLICY PAGES'!O3:O14,"Untested") -> 10 | F12: =COUNTIF('POLICY PAGES'!O3:O14,"N/A") -> 0 | G12: =IF(B12=0,0,(B12-E12-F12)/B12) -> 0 | H12: =IF((B12-E12-F12)=0,0,C12/(B12-E12-F12)) -> 0
A13: TOTAL | B13: =SUM(B4:B12) -> 598 | C13: =SUM(C4:C12) -> #VALUE! | D13: =SUM(D4:D12) -> #VALUE! | E13: =SUM(E4:E12) -> #VALUE! | F13: =SUM(F4:F12) -> #VALUE!

Sheet HOME
A1: TC_ID | B1: Screen | C1: US_Mapping | D1: Module | E1: Title | F1: Type | G1: Priority | H1: Pre-condition | I1: Steps | J1: Expected Result | K1: Actual Result | L1: Action Type | M1: Create TCs Type | N1: Execution Type | O1: Result_R1 | P1: Test Date_R1 | Q1: Tester_R1 | R1: Bug ID_R1 | S1: Bug Desc_R1 | T1: Result_R2 | U1: Test Date_R2 | V1: Tester_R2 | W1: Bug ID_R2 | X1: Bug Desc_R2 | Y1: Evidence | Z1: Notes | AA1: Review_Manual (Feedback)
A2: 📌 UI/UX
A3: TC_HOME_UI_009 | B3: MH Trang chủ | C3: US-HP-03 | D3: AI Input | E3: Home page: Nút Generate style đúng | F3: 🎨 UI/UX | G3: **🔴 P0** | I3: 1. Truy cập vào trang 2. Quan sát nút Generate bên phải input box | J3: Nút hiển thị: text 'Tạo ngay' + icon Wand2 ✨. Background teal gradient (#0D9488), text trắng, bo tròn. Nút nằm bên phải input | L3: Add new | M3: By AI | N3: Manual | O3: Untested | T3: Untested
A4: TC_HOME_UI_008 | B4: MH Trang chủ | C4: US-HP-03 | D4: AI Input | E4: Home page: AI Input Box placeholder đúng | F4: 🎨 UI/UX | G4: **🟠 P1** | I4: 1. Truy cập vào trang 2. Quan sát ô nhập liệu AI ở giữa trang | J4: Placeholder hiển thị: 'Bạn muốn kể gì trên áo?'. Input dạng chat conversational, bo tròn. Animated gradient border (teal-cyan). Có nút đính kèm ảnh tham khảo bên trái, nút 'Tạo ngay' bên phải | L4: Add new | M4: By AI | N4: Manual | O4: Untested | T4: Untested
A5: TC_HOME_UI_010 | B5: MH Trang chủ | C5: US-HP-03 | D5: AI Input | E5: Home page: 6 Style Tags hiển thị đầy đủ | F5: 🎨 UI/UX | G5: **🟠 P1** | I5: 1. Truy cập vào trang 2. Quan sát các tag phía dưới AI Input Box | J5: Hiển thị đầy đủ 6 tags: 'Tối giản', 'Streetwear', 'Anime', 'Retro', 'Y2K vibes', 'Nghệ thuật'. Mỗi tag có emoji riêng (🎯🔥🌸🎸✨🎨), bo tròn full, gradient border khi selected. Font size ~14px | L5: Add new | M5: By AI | N5: Manual | O5: Untested | T5: Untested
A6: TC_HOME_UI_011 | B6: MH Trang chủ | C6: US-HP-03 | D6: AI Input | E6: Home page: Nút 'Chọn từ mẫu có sẵn' hiển thị | F6: 🎨 UI/UX | G6: **🟠 P1** | I6: 1. Truy cập vào trang 2. Quan sát 2 nút phía dưới Style Tags | J6: Nút 'Chọn từ mẫu có sẵn' hiển thị: Grid icon tím, subtitle 'Khám phá thư viện mẫu', background trắng, border tím. Font size title ~16px, subtitle ~13px | L6: Add new | M6: By AI | N6: Manual | O6: Untested | T6: Untested
A7: TC_HOME_UI_012 | B7: MH Trang chủ | C7: US-HP-03 | D7: AI Input | E7: Home page: Nút 'Tải lên ảnh của bạn' hiển thị | F7: 🎨 UI/UX | G7: **🟠 P1** | I7: 1. Truy cập vào trang 2. Quan sát nút thứ hai phía dưới Style Tags | J7: Nút 'Tải lên ảnh của bạn' hiển thị: Upload icon tím, subtitle 'Sử dụng file thiết kế riêng', background trắng, border tím. Font size title ~16px, subtitle ~13px | L7: Add new | M7: By AI | N7: Manual | O7: Untested | T7: Untested
A8: TC_HOME_016 | B8: MH Trang chủ | C8: US-HP-05 | D8: Accessibility | E8: Home page: Heading hierarchy đúng chuẩn | F8: 🎨 UI/UX | G8: **🟢 P2** | I8: 1. Truy cập vào trang 2. Kiểm tra source code: kiểm tra thứ tự h1, h2, h3 | J8: Trang chỉ có 1 thẻ h1 (Headline chính). Các heading phụ sử dụng h2, h3 đúng thứ tự. Không skip level (h1 → h3) | L8: Add new | M8: By AI | N8: Manual | O8: Untested | T8: Untested
A9: TC_HOME_017 | B9: MH Trang chủ | C9: US-HP-05 | D9: Accessibility | E9: Home page: Keyboard navigation (Tab order) | F9: 🎨 UI/UX | G9: **🟢 P2** | I9: 1. Truy cập vào trang 2. Nhấn Tab liên tục từ đầu trang | J9: Tab order hợp lý: Logo → Menu items → 'Thiết kế ngay' → AI Input → Generate → Style Tags → Action Buttons. Focus ring hiển thị rõ ràng | L9: Add new | M9: By AI | N9: Manual | O9: Untested | T9: Untested
A10: TC_HOME_UI_006 | B10: MH Trang chủ | C10: US-HP-02 | D10: Hero | E10: Home page: Headline text đúng nội dung (Updated v28) | F10: 🎨 UI/UX | G10: **🔴 P0** | I10: 1. Truy cập vào trang 2. Quan sát tiêu đề chính Hero section | J10: Headline hiển thị: 'Mỗi chiếc áo, một câu chuyện'. Phần highlight có màu tím gradient. Font size lớn (~48-56px), bold | L10: Add new | M10: By AI | N10: Manual | O10: Untested | T10: Untested
A11: TC_HOME_UI_005 | B11: MH Trang chủ | C11: US-HP-02 | D11: Hero | E11: Home page: Badge 'AI-Powered Design' hiển thị | F11: 🎨 UI/UX | G11: **🟢 P2** | I11: 1. Truy cập vào trang 2. Quan sát phần trên cùng Hero section | J11: Badge/chip hiển thị: '✨ AI-Powered Design' với background tím nhạt, icon sparkle, text tím đậm | L11: Add new | M11: By AI | N11: Manual | O11: Untested | T11: Untested
A12: TC_HOME_UI_007 | B12: MH Trang chủ | C12: US-HP-02 | D12: Hero | E12: Home page: Subtitle text đúng nội dung | F12: 🎨 UI/UX | G12: **🟢 P2** | I12: 1. Truy cập vào trang 2. Quan sát dòng mô tả bên dưới Headline | J12: Subtitle hiển thị: 'Kể mình nghe ý tưởng của bạn — mình biến nó thành artwork trên áo trong vài giây!'. Text xám, centered. Font size ~16-18px | L12: Add new | M12: By AI | N12: Manual | O12: Untested | T12: Untested
A13: TC_HOME_UI_016 | B13: MH Trang chủ | C13: US-HP-02 | D13: Hero | E13: Home page: Background gradient Hero section | F13: 🎨 UI/UX | G13: **🟢 P2** | I13: 1. Truy cập vào trang 2. Quan sát nền trang Hero section | J13: Nền hiển thị gradient nhẹ: trắng lavender (#F8F7FF) với các hiệu ứng trang trí 2 bên (hình trang trí mờ/blur) | L13: Add new | M13: By AI | N13: Manual | O13: Untested | T13: Untested
A14: TC_HOME_UI_003 | B14: MH Trang chủ | C14: US-HP-01 | D14: Home - Header | E14: Home page: Nút 'Thiết kế ngay' style đúng | F14: 🎨 UI/UX | G14: **🔴 P0** | I14: 1. Truy cập vào trang 2. Quan sát nút CTA góc phải header | J14: Nút 'Thiết kế ngay' hiển thị: background gradient tím→đỏ (#7C3AED→#E11D48), text trắng, bo tròn (rounded-full), font semi-bold | L14: Add new | M14: By AI | N14: Manual | O14: Untested | T14: Untested
... A30: TC_ERR_UI_001 | B30: Error Page | C30: Global | D30: Error - 404 | E30: Trang 404: URL không tồn tại | F30: 🎨 UI/UX | G30: **🟠 P1** | I30: 1. Truy cập URL không tồn tại (VD: /abc123) 2. Quan sát trang | J30: Hiển thị trang 404 thân thiện: illustration, text 'Trang không tồn tại', nút 'Về trang chủ'. KHÔNG hiển thị lỗi kỹ thuật | L30: Add new | M30: By AI | N30: Manual | O30: Untested | T30: Untested
A31: 📌 Validation
A32: TC_HOME_009 | B32: MH Trang chủ | C32: US-HP-03 | D32: AI Input | E32: Click Generate khi input rỗng | F32: ⚠️ Negative | G32: **🔴 P0** | I32: 1. Truy cập vào trang 2. Không nhập gì vào AI Input Box 3. Click nút 'Generate' | J32: Không validate. Chuyển sang Design Studio với thiết kế mặc định | L32: Add new | M32: By AI | N32: Manual | O32: Untested | T32: Untested
A33: TC_HOME_019 | B33: MH Trang chủ | C33: US-HP-03 | D33: AI Input | E33: AI prompt cực dài 5000+ ký tự (BVA max) | F33: ⚠️ Negative | G33: **🟠 P1** | I33: 1. Truy cập vào trang 2. Nhập text 5000+ ký tự vào AI Input Box 3. Click 'Generate' | J33: Input truncate hoặc hiển thị validation: 'Mô tả quá dài (tối đa X ký tự)'. Không gửi payload quá lớn | L33: Add new | M33: By AI | N33: Manual | O33: Untested | T33: Untested
A34: TC_HOME_020 | B34: MH Trang chủ | C34: US-HP-03 | D34: AI Input | E34: AI prompt chỉ có whitespace/spaces | F34: ⚠️ Negative | G34: **🟠 P1** | I34: 1. Truy cập vào trang 2. Nhập text: ' ' (chỉ spaces) vào AI Input Box 3. Click 'Generate' | J34: Hiển thị validation tương tự input rỗng: 'Vui lòng nhập mô tả'. Trim whitespace trước khi validate | L34: Add new | M34: By AI | N34: Manual | O34: Untested | T34: Untested
A35: TC_HOME_018 | B35: MH Trang chủ | C35: US-HP-03 | D35: AI Input | E35: AI prompt chỉ có 1 ký tự (BVA min) | F35: ⚠️ Negative | G35: **🟢 P2** | I35: 1. Truy cập vào trang 2. Nhập text: 'A' (1 ký tự) vào AI Input Box 3. Click 'Generate' | J35: Hiển thị validation: 'Mô tả quá ngắn' hoặc chấp nhận và xử lý. Behavior rõ ràng, không crash | L35: Add new | M35: By AI | N35: Manual | O35: Untested | T35: Untested
A36: TC_HOME_010 | B36: MH Trang chủ | C36: US-HP-01 | D36: Navigation | E36: Menu 'Sản phẩm' trỏ đúng route | F36: ⚠️ Negative | G36: **🟠 P1** | I36: 1. Truy cập vào trang 2. Click menu 'Sản phẩm' trên navigation 3. Quan sát URL | J36: URL chuyển sang /products hoặc trang sản phẩm tương ứng. Không trỏ ngược về /home/ (BUG hiện tại: trỏ sai) | L36: Add new | M36: By AI | N36: Manual | O36: Untested | T36: Untested
A37: TC_HOME_011 | B37: MH Trang chủ | C37: US-HP-01 | D37: Navigation | E37: Menu 'Dịch vụ' trỏ đúng route | F37: ⚠️ Negative | G37: **🟠 P1** | I37: 1. Truy cập vào trang 2. Click menu 'Dịch vụ' trên navigation 3. Quan sát URL | J37: URL chuyển sang /services hoặc trang dịch vụ tương ứng. Không trỏ ngược về /home/ (BUG hiện tại: trỏ sai) | L37: Add new | M37: By AI | N37: Manual | O37: Untested | T37: Untested
A38: TC_HOME_012 | B38: MH Trang chủ | C38: US-HP-01 | D38: Navigation | E38: Menu 'Liên hệ' trỏ đúng route | F38: ⚠️ Negative | G38: **🟠 P1** | I38: 1. Truy cập vào trang 2. Click menu 'Liên hệ' trên navigation 3. Quan sát URL | J38: URL chuyển sang /contact hoặc trang liên hệ tương ứng. Không trỏ ngược về /home/ (BUG hiện tại: trỏ sai) | L38: Add new | M38: By AI | N38: Manual | O38: Untested | T38: Untested
A39: 📌 Functional
A40: TC_HOME_004 | B40: MH Trang chủ | C40: US-HP-03 | D40: AI Input | E40: Nhập prompt vào AI Input Box và click Generate | F40: ✅ Positive | G40: **🔴 P0** | I40: 1. Truy cập vào trang 2. Nhập text: 'Áo minimalist hoa sakura' vào AI Input Box 3. Click nút 'Generate' | J40: Chuyển sang Design Studio và hiển thị kết quả AI. Prompt được xử lý. Loading state hiển thị | L40: Add new | M40: By AI | N40: Manual | O40: Untested | T40: Untested
A41: TC_HOME_025 | B41: MH Trang chủ | C41: US-HP-03 | D41: AI Input | E41: Click Generate sau khi chọn Style Tag | F41: ✅ Positive | G41: **🔴 P0** | I41: 1. Truy cập vào trang 2. Click tag 'Streetwear' 3. Nhập text: 'Áo phong cách đường phố' 4. Click nút 'Generate' | J41: Prompt được gửi kèm style tag đã chọn. Loading state hiển thị. Chuyển sang Design Studio với style 'Streetwear' | L41: Add new | M41: By AI | N41: Manual | O41: Untested | T41: Untested
A42: TC_HOME_005 | B42: MH Trang chủ | C42: US-HP-03 | D42: AI Input | E42: Click Style Tag thay đổi trạng thái | F42: ✅ Positive | G42: **🟠 P1** | I42: 1. Truy cập vào trang 2. Click tag 'Tối giản' 3. Click tag 'Anime' | J42: Tag được chọn có highlight (background đổi màu hoặc border đậm). Chỉ 1 tag active cùng lúc — tag trước đó tự động bỏ highlight khi chọn tag mới | L42: Add new | M42: By AI | N42: Manual | O42: Untested | T42: Untested
A43: TC_HOME_006 | B43: MH Trang chủ | C43: US-HP-03 | D43: AI Input | E43: Click nút 'Chọn từ mẫu có sẵn' | F43: ✅ Positive | G43: **🟠 P1** | I43: 1. Truy cập vào trang 2. Click nút 'Chọn từ mẫu có sẵn' | J43: Chuyển sang Design Studio và mở tab thư viện mẫu hiển thị danh sách templates có sẵn | L43: Add new | M43: By AI | N43: Manual | O43: Untested | T43: Untested
A44: TC_HOME_007 | B44: MH Trang chủ | C44: US-HP-03 | D44: AI Input | E44: Click nút 'Tải lên ảnh của bạn' | F44: ✅ Positive | G44: **🟠 P1** | I44: 1. Truy cập vào trang 2. Click nút 'Tải lên ảnh của bạn' | J44: Chuyển sang Design Studio và mở thư viện ảnh cho phép chọn file ảnh để tải lên. Chấp nhận formats: PNG, JPG, SVG | L44: Add new | M44: By AI | N44: Manual | O44: Untested | T44: Untested
A45: TC_HOME_021 | B45: MH Trang chủ | C45: US-HP-03 | D45: AI Input | E45: Click tag 'Streetwear' và verify style được áp dụng | F45: ✅ Positive | G45: **🟠 P1** | I45: 1. Truy cập vào trang 2. Click tag 'Streetwear' (🔥 icon) | J45: Tag 'Streetwear' highlight (border đậm hoặc background đổi). Các tag khác bỏ highlight. Prompt box cập nhật style tương ứng | L45: Add new | M45: By AI | N45: Manual | O45: Untested | T45: Untested
A46: TC_HOME_022 | B46: MH Trang chủ | C46: US-HP-03 | D46: AI Input | E46: Click tag 'Retro' và verify style được áp dụng | F46: ✅ Positive | G46: **🟠 P1** | I46: 1. Truy cập vào trang 2. Click tag 'Retro' (🎸 icon) | J46: Tag 'Retro' highlight. Các tag khác bỏ highlight | L46: Add new | M46: By AI | N46: Manual | O46: Untested | T46: Untested
A47: TC_HOME_023 | B47: MH Trang chủ | C47: US-HP-03 | D47: AI Input | E47: Click tag 'Y2K vibes' và verify style được áp dụng | F47: ✅ Positive | G47: **🟠 P1** | I47: 1. Truy cập vào trang 2. Click tag 'Y2K vibes' (✨ icon) | J47: Tag 'Y2K vibes' highlight. Các tag khác bỏ highlight | L47: Add new | M47: By AI | N47: Manual | O47: Untested | T47: Untested
A48: TC_HOME_024 | B48: MH Trang chủ | C48: US-HP-03 | D48: AI Input | E48: Click tag 'Nghệ thuật' và verify style được áp dụng | F48: ✅ Positive | G48: **🟠 P1** | I48: 1. Truy cập vào trang 2. Click tag 'Nghệ thuật' (🎨 icon) | J48: Tag 'Nghệ thuật' highlight. Các tag khác bỏ highlight | L48: Add new | M48: By AI | N48: Manual | O48: Untested | T48: Untested
A49: TC_HOME_008 | B49: MH Trang chủ | C49: US-HP-03 | D49: AI Input | E49: Submit AI Input bằng phím Enter | F49: ✅ Positive | G49: **🟢 P2** | I49: 1. Truy cập vào trang 2. Nhập text: 'Áo vintage rock band' 3. Nhấn phím Enter | J49: Form submit thành công — chuyển sang Design Studio hoặc hiển thị loading state. Behavior tương đương click nút Generate | L49: Add new | M49: By AI | N49: Manual | O49: Untested | T49: Untested
A50: TC_HOME_026 | B50: MH Trang chủ | C50: US-HP-02 | D50: Hero | E50: Click badge '✨ AI-Powered Design' | F50: ✅ Positive | G50: **🟢 P2** | I50: 1. Truy cập vào trang 2. Click badge '✨ AI-Powered Design' ở Hero section | J50: Badge không phải link → không redirect | L50: Add new | M50: By AI | N50: Manual | O50: Untested | T50: Untested
A51: TC_HOME_001 | B51: MH Trang chủ | C51: US-HP-01 | D51: Navigation | E51: Click nút 'Thiết kế ngay' mở Design Studio | F51: ✅ Positive | G51: **🔴 P0** | I51: 1. Truy cập vào trang 2. Mở /home/ 3. Click nút 'Thiết kế ngay' trên header | J51: Chuyển sang trang Design Studio. Canvas mockup áo thun hiển thị. Header đổi thành header Design Studio | L51: Add new | M51: By AI | N51: Manual | O51: Untested | T51: Untested
... A55: TC_ERR_F_001 | B55: SPA Routing | C55: Global | D55: Error - Navigation | E55: 404 → Click 'Về trang chủ' | F55: ✅ Positive | G55: **🟢 P2** | I55: 1. Truy cập URL không tồn tại 2. Click nút 'Về trang chủ' | J55: Redirect về /home/ thành công | L55: Add new | M55: By AI | N55: Manual | O55: Untested | T55: Untested
A56: 📌 Security
A57: TC_HOME_013 | B57: MH Trang chủ | C57: US-HP-03 | D57: AI Input | E57: Nhập prompt chứa ký tự đặc biệt và XSS | F57: ⚠️ Negative | G57: **🟠 P1** | I57: 1. Truy cập vào trang 2. Nhập text: '<script>alert(1)</script>' vào AI Input Box 3. Click Generate | J57: Hệ thống sanitize input. Không execute script. Prompt được escape đúng | L57: Add new | M57: By AI | N57: Manual | O57: Untested | T57: Untested
A58: 📌 Performance
...

Sheet DESIGN STUDIO
A1: TC_ID | B1: Screen | C1: US_Mapping | D1: Module | E1: Title | F1: Type | G1: Priority | H1: Pre-condition | I1: Steps | J1: Expected Result | K1: Actual Result | L1: Action Type | M1: Create TCs Type | N1: Execution Type | O1: Result_R1 | P1: Test Date_R1 | Q1: Tester_R1 | R1: Bug ID_R1 | S1: Bug Desc_R1 | T1: Result_R2 | U1: Test Date_R2 | V1: Tester_R2 | W1: Bug ID_R2 | X1: Bug Desc_R2 | Y1: Evidence | Z1: Notes | AA1: Review_Manual (Feedback)
A2: 📌 UI/UX
A3: TC_DS_UI_001 | B3: DS - Chung | C3: US-DS-01 | D3: DS Chung - Header | E3: Design Studio: Header hiển thị đầy đủ | F3: 🎨 UI/UX | G3: **🟠 P1** | I3: 1. Mở Design Studio (click 'Thiết kế ngay') 2. Quan sát header | J3: Header hiển thị: ← 'Quay lại' (trái), Logo 'Tryonic' icon (trái), text 'Design Studio' (giữa), Credits badge + nút 'Chia sẻ' + icon User + icon Giỏ hàng (phải) | L3: Add new | M3: By AI | N3: Manual | O3: Untested | T3: Untested
A4: TC_DS_UI_002 | B4: DS - Chung | C4: US-DS-01 | D4: DS Chung - Header | E4: Design Studio: Credits badge hiển thị số dư | F4: 🎨 UI/UX | G4: **🟠 P1** | I4: 1. Mở Design Studio 2. Quan sát góc phải header | J4: Hiển thị: '12 Credits' + nút 'Chia sẻ' (thay vì Nạp). Credits badge có icon coin/circle | L4: Add new | M4: By AI | N4: Manual | O4: Untested | T4: Untested
A5: TC_DS_UI_003 | B5: DS - Sidebar | C5: US-DS-02 | D5: Sidebar | E5: Design Studio: Sidebar trái hiển thị đầy đủ công cụ | F5: 🎨 UI/UX | G5: **🟠 P1** | I5: 1. Mở Design Studio 2. Quan sát sidebar trái | J5: Hiển thị 7 công cụ theo thứ tự: Hoàn Tác, Làm Lại, Mặt Sau, Thu Phóng, Thư Viện, Thử Đồ với AI, Chia Sẻ. Mỗi công cụ có icon + text label. 'Thử Đồ với AI' disabled khi chưa có artwork | L5: Add new | M5: By AI | N5: Manual | O5: Untested | T5: Untested
A6: TC_DS_UI_004 | B6: DS - Canvas | C6: US-DS-03 | D6: DS Chung - Canvas | E6: Design Studio: Canvas mockup áo mặc định | F6: 🎨 UI/UX | G6: **🔴 P0** | I6: 1. Mở Design Studio 2. Quan sát canvas trung tâm | J6: Hiển thị mockup áo thun trắng trên nền xám. Vùng thiết kế được đánh dấu bằng đường nét đứt xanh cyan. Text hướng dẫn: 'Nhấn "Thêm Hình", "Thư Viện" hoặc "AI Artwork" để bắt đầu thiết kế' | L6: Add new | M6: By AI | N6: Manual | O6: Untested | T6: Untested
A7: TC_DES_UI_031 | B7: DS - Editor/Canvas | C7: US-15 | D7: Editor - Canvas | E7: Canvas: Smart Guides (Bắt dính thông minh) | F7: 🎨 UI/UX | G7: **🟠 P1** | I7: 1. Truy cập vào trang 2. Kéo layer vào chính giữa Canvas (Vertical/Horizontal)\n2. Kéo ngang hàng với một layer khác | J7: Hiển thị các đường viền đỏ/xanh (Guides) tự động bắt dính báo hiệu layer đã vô giữa hoặc ngay ngắn | L7: Add new | M7: By AI | N7: Manual | O7: Untested | T7: Untested
A8: TC_DES_UI_032 | B8: DS - Editor/Canvas | C8: US-15 | D8: Editor - Canvas | E8: Canvas: Keyboard Shortcuts cơ bản | F8: 🎨 UI/UX | G8: **🟠 P1** | I8: 1. Truy cập vào trang 2. Nhấn Delete/Backspace\n2. Nhấn Ctrl+Z / Ctrl+Y\n3. Nhấn Ctrl+C rồi Ctrl+V | J8: 1. Layer bị xóa\n2. Undo/Redo chính xác\n3. Layer được copy/paste ngay cạnh layer gốc | L8: Add new | M8: By AI | N8: Manual | O8: Untested | T8: Untested
A9: TC_DES_UI_029a | B9: DS - Editor/Canvas | C9: US-15 | D9: Editor - Canvas Viewpoint | E9: Canvas: Zoom In / Zoom Out (bằng UI Buttons) | F9: 🎨 UI/UX | G9: **🟠 P1** | I9: 1. Truy cập vào trang Editor 2. Click nút + (Zoom In) và nút - (Zoom Out) trên UI | J9: Canvas và các layer phóng to/thu nhỏ mượt mà. Tâm zoom focus vào giữa màn hình. | L9: Add new | M9: By AI | N9: Manual | O9: Untested | T9: Untested
A10: TC_DES_UI_029b | B10: DS - Editor/Canvas | C10: US-15 | D10: Editor - Canvas Viewpoint | E10: Canvas: Zoom In / Zoom Out (bằng Ctrl + Scroll) | F10: 🎨 UI/UX | G10: **🟠 P1** | I10: 1. Truy cập vào trang Editor 2. Nhấn giữ phím Ctrl và lăn chuột lên (Zoom In) / xuống (Zoom Out) | J10: Canvas và các layer phóng to/thu nhỏ mức zoom tương ứng mượt mà. Tâm zoom focus vào vị trí con trỏ chuột. | L10: Add new | M10: By AI | N10: Manual | O10: Untested | T10: Untested
A11: TC_DES_UI_030a | B11: DS - Editor/Canvas | C11: US-15 | D11: Editor - Canvas Viewpoint | E11: Canvas: Pan (Di chuyển vùng nhìn bằng Space + Drag) | F11: 🎨 UI/UX | G11: **🟠 P1** | I11: 1. Truy cập vào trang Editor và zoom canvas lớn hơn màn hình 2. Nhấn giữ phím Space và click kéo thả chuột (Drag) | J11: Con trỏ đổi thành hình bàn tay (hand tool). Vùng nhìn di chuyển mượt mà lên/xuống/trái/phải để xem các góc khác của thiết kế. | L11: Add new | M11: By AI | N11: Manual | O11: Untested | T11: Untested
A12: TC_UIUX_003 | B12: DS - Editor/Canvas | C12: US-15 | D12: Editor - Canvas Viewpoint | E12: Verify Smart Guides magnetic alignment | F12: 🎨 UI/UX | G12: **🟠 P1** | I12: 1. Truy cập vào trang 2. Mở Editor 3. Kéo layer A di chuyển lại gần layer B / tâm canvas | J12: Chớp xuất hiện đường viền (guide) đỏ/xanh báo đã căn giữa/trái/phải | L12: Add new | M12: By AI | N12: Manual | O12: Untested | T12: Untested
A13: TC_UIUX_004 | B13: DS - Editor/Canvas | C13: US-15 | D13: Editor - Canvas Viewpoint | E13: Verify Keyboard Shortcuts mapping | F13: 🎨 UI/UX | G13: **🟠 P1** | I13: 1. Truy cập vào trang 2. Mở Editor 3. Chọn layer Text 4. Nhấn Ctrl+C rồi Ctrl+V rồi Delete | J13: Copy ra layer mới và sau đó xóa layer thành công | L13: Add new | M13: By AI | N13: Manual | O13: Untested | T13: Untested
A14: TC_UIUX_005 | B14: DS - Editor/Canvas | C14: US-16 | D14: Editor - Canvas Viewpoint | E14: Verify Layer Opacity slider | F14: 🎨 UI/UX | G14: **🟠 P1** | I14: 1. Truy cập vào trang 2. Mở Editor 3. Chọn layer 4. Kéo thanh trượt thay đổi Opacity xuống 50% | J14: Layer trở nên trong suốt 50%, nhìn xuyên thấu xuống background | L14: Add new | M14: By AI | N14: Manual | O14: Untested | T14: Untested
... A59: TC_GAL_UI_820 | B59: DS - Responsive | C59: Global | D59: Responsive (iPhone) | E59: Màn hình Gallery: Responsive trên iPhone (Safari/Chrome, Dọc - Portrait) | F59: 🎨 UI/UX | G59: **🔴 P0** | I59: 1. Truy cập trang Gallery trên iPhone ở chế độ cầm dọc (Portrait). 2. Cuộn lên/xuống toàn trang. 3. Tap thử các nút bấm, input field. | J59: Không xuất hiện thanh cuộn ngang thừa. Các khối nội dung hiển thị cột đơn (stacking). Các nút bấm (Touch Targets) không quá nhỏ, không nằm sát mép màn hình (có padding viền an toàn hợp lý). | L59: Add new | M59: By AI | N59: Manual | O59: Untested | T59: Untested
A60: 📌 Validation
A61: TC_DS_016 | B61: DS - Sidebar | C61: US-DS-02 | D61: Sidebar | E61: Click 'Hoàn Tác' khi không có action nào | F61: ⚠️ Negative | G61: **🟢 P2** | I61: 1. Mở Design Studio (canvas trống, chưa thao tác) 2. Click icon 'Hoàn Tác' | J61: Nút Undo disabled hoặc không có phản hồi. Không crash. Không thay đổi canvas | L61: Add new | M61: By AI | N61: Manual | O61: Untested | T61: Untested
A62: TC_DS_SC_038 | B62: DS - Canvas | C62: US-DS-03 | D62: Canvas - Undo | E62: Nút Undo disabled khi history rỗng | F62: ⚠️ Negative | G62: **🟢 P2** | I62: 1. Mở DS mới (chưa thao tác) 2. Quan sát nút Undo trên sidebar | J62: Nút Undo có opacity-40 (mờ). Click không có hiệu ứng. canUndo = false | L62: Add new | M62: By AI | N62: Manual | O62: Untested | T62: Untested
A63: TC_DS_SC_039 | B63: DS - Canvas | C63: US-DS-03 | D63: Canvas - Undo | E63: Nút Redo disabled khi không có undo | F63: ⚠️ Negative | G63: **🟢 P2** | I63: 1. Mở DS mới hoặc sau khi thêm element (chưa undo) 2. Quan sát nút Redo | J63: Nút Redo có opacity-40 (mờ). canRedo = false | L63: Add new | M63: By AI | N63: Manual | O63: Untested | T63: Untested
A64: TC_DES_020 | B64: DS - Editor/Canvas | C64: US-17 | D64: Editor - History | E64: Undo khi không có history | F64: ✅ Boundary | G64: **🟢 P2** | I64: 1. Truy cập vào trang 2. Click Undo | J64: Undo disabled hoặc không có hiệu ứng | L64: Add new | M64: By AI | N64: Manual | O64: Untested | T64: Untested
A65: TC_DES_022 | B65: DS - Editor/Canvas | C65: US-18 | D65: Editor - Save | E65: Save design khi Guest → yêu cầu login | F65: ⚠️ Negative | G65: **🔴 P0** | I65: 1. Truy cập vào trang 2. Click 'Save' | J65: Hiện popup login. Sau login → save + migrate | L65: Add new | M65: By AI | N65: Manual | O65: Untested | T65: Untested
A66: TC_DES_010 | B66: DS - Editor/Canvas | C66: US-14 | D66: Editor - Text | E66: Text rỗng | F66: ⚠️ Negative | G66: **🟠 P1** | I66: 1. Truy cập vào trang 2. Click 'Add Text' 3. Không nhập gì 4. Click ra ngoài | J66: Không tạo layer rỗng hoặc tự xóa layer trống | L66: Add new | M66: By AI | N66: Manual | O66: Untested | T66: Untested
A67: TC_DES_011 | B67: DS - Editor/Canvas | C67: US-14 | D67: Editor - Text | E67: Text rất dài (500+ ký tự) | F67: ✅ Boundary | G67: **🟠 P1** | I67: 1. Truy cập vào trang 2. Nhập text 500 ký tự | J67: Text wrap hoặc warning. Không vỡ canvas | L67: Add new | M67: By AI | N67: Manual | O67: Untested | T67: Untested
A68: TC_DSP_V_001 | B68: DS - Popup Sản phẩm | C68: US-DS-04 | D68: DS Sản phẩm - Modal | E68: Chọn size không có sẵn (nếu hết hàng) | F68: ⚠️ Negative | G68: **🟠 P1** | I68: 1. Mở Design Studio → Popup Sản phẩm (ProductSelectorModal) 2. Click size bị disabled/hết hàng | J68: Size không thể chọn. Hiển thị tooltip/thông báo 'Hết hàng' hoặc size bị gạch bỏ (strikethrough). Không crash | L68: Add new | M68: By AI | N68: Manual | O68: Untested | T68: Untested
A69: TC_DSP_V_002 | B69: DS - Popup Sản phẩm | C69: US-DS-04 | D69: DS Sản phẩm - Modal | E69: Chuyển tab khác rồi quay lại 'SẢN PHẨM' — trạng thái giữ nguyên | F69: ⚠️ Negative | G69: **🟢 P2** | I69: 1. Mở DS → Popup Sản phẩm (ProductSelectorModal) → Chọn màu Đen, size XL 2. Chuyển sang AI Panel 3. Quay lại popup sản phẩm | J69: Màu Đen và size XL vẫn được giữ nguyên. Không reset về mặc định | L69: Add new | M69: By AI | N69: Manual | O69: Untested | T69: Untested
A70: TC_DES_003 | B70: DS - Thư viện Ảnh | C70: US-13 | D70: Editor - Upload | E70: Upload file > 25MB | F70: ⚠️ Negative | G70: **🔴 P0** | I70: 1. Truy cập vào trang 2. Click Upload 3. Chọn file 30MB | J70: Hiển thị lỗi: 'File vượt quá 25MB' | L70: Add new | M70: By AI | N70: Manual | O70: Untested | T70: Untested
A71: TC_DES_004 | B71: DS - Thư viện Ảnh | C71: US-13 | D71: Editor - Upload | E71: Upload file format không hỗ trợ (PDF) | F71: ⚠️ Negative | G71: **🔴 P0** | I71: 1. Truy cập vào trang 2. Click Upload 3. Chọn file PDF | J71: Hiển thị lỗi: 'Chỉ hỗ trợ PNG/JPG' | L71: Add new | M71: By AI | N71: Manual | O71: Untested | T71: Untested
A72: TC_DES_006 | B72: DS - Thư viện Ảnh | C72: US-13 | D72: Editor - Upload | E72: Upload ảnh < 150 DPI - cảnh báo chất lượng | F72: ⚠️ Negative | G72: **🔴 P0** | I72: 1. Truy cập vào trang 2. Upload ảnh 72 DPI | J72: Hiển thị warning: 'Low Quality - May be blurry when printed' | L72: Add new | M72: By AI | N72: Manual | O72: Untested | T72: Untested
... A88: TC_DS_SC_018 | B88: DS - Chung | C88: US-DS-01 | D88: Auth Modal | E88: Submit form trống → validation error | F88: ⚠️ Negative | G88: **🟠 P1** | I88: 1. Mở InlineAuthModal 2. Không nhập gì → Click 'Đăng nhập' | J88: Hiển thị error: 'Vui lòng điền đầy đủ thông tin'. Error box bg-red-50, border-red-100, icon AlertCircle | L88: Add new | M88: By AI | N88: Manual | O88: Untested | T88: Untested
A89: 📌 Functional
A90: TC_DS_001 | B90: DS - Chung | C90: US-DS-01 | D90: DS Chung - Header | E90: Click 'Quay lại' từ Design Studio về trang chủ | F90: ✅ Positive | G90: **🟠 P1** | I90: 1. Mở Design Studio 2. Click '← Quay lại' | J90: Chuyển về trang /home/. Design Studio đóng lại | L90: Add new | M90: By AI | N90: Manual | O90: Untested | T90: Untested
A91: TC_DS_008a | B91: DS - Chung | C91: US-DS-01 | D91: DS Chung - Header | E91: Click icon User khi đã đăng nhập | F91: ✅ Positive | G91: **🟢 P2** | I91: 1. Đăng nhập → Mở Design Studio 2. Click icon User (góc phải header) | J91: Mở trang profile/account. Hiển thị thông tin tài khoản | L91: Add new | M91: By AI | N91: Manual | O91: Untested | T91: Untested
A92: TC_DS_008b | B92: DS - Chung | C92: US-DS-01 | D92: DS Chung - Header | E92: Click icon User khi chưa đăng nhập | F92: ✅ Positive | G92: **🟢 P2** | I92: 1. Truy cập Guest → Mở Design Studio 2. Click icon User (góc phải header) | J92: Hiển thị popup login. Cho phép đăng nhập hoặc đăng ký | L92: Add new | M92: By AI | N92: Manual | O92: Untested | T92: Untested
A93: TC_DS_009 | B93: DS - Chung | C93: US-DS-01 | D93: DS Chung - Header | E93: Click icon Giỏ hàng trên header | F93: ✅ Positive | G93: **🟢 P2** | I93: 1. Mở Design Studio 2. Click icon Giỏ hàng (góc phải header) | J93: Mở trang giỏ hàng hoặc sidebar cart. Hiển thị số lượng items (badge) | L93: Add new | M93: By AI | N93: Manual | O93: Untested | T93: Untested
A94: TC_DS_010 | B94: DS - Chung | C94: US-DS-01 | D94: DS Chung - Header | E94: Click nút 'Nạp' credits | F94: ✅ Positive | G94: **🟢 P2** | I94: 1. Mở Design Studio 2. Click nút 'Nạp' bên cạnh credits | J94: Hiển thị tooltip thông tin credits. Không mở trang nạp riêng | L94: Add new | M94: By AI | N94: Manual | O94: Untested | T94: Untested
A95: TC_DS_028 | B95: DS - Chung | C95: US-DS-01 | D95: DS Chung - Header | E95: Click logo 'Tryonic' trên header | F95: ✅ Positive | G95: **🟢 P2** | I95: 1. Mở Design Studio 2. Click logo 'Tryonic' (icon) trên header | J95: Redirect về trang chủ /home/ hoặc không phản hồi (nếu logo không phải link). Behavior nhất quán | L95: Add new | M95: By AI | N95: Manual | O95: Untested | T95: Untested
A96: TC_DS_SC_012 | B96: DS - Chung | C96: US-DS-01 | D96: DS Header - Cart | E96: Icon giỏ hàng hiển thị badge số lượng | F96: ✅ Positive | G96: **🟠 P1** | I96: 1. Thêm sản phẩm vào giỏ 2. Mở Design Studio | J96: Icon ShoppingBag hiển thị badge đỏ (#EF4444) với số lượng items. Badge nhỏ (w-4 h-4), font 10px, text trắng | L96: Add new | M96: By AI | N96: Manual | O96: Untested | T96: Untested
A97: TC_DS_SC_013 | B97: DS - Chung | C97: US-DS-01 | D97: DS Header - Cart | E97: Click icon giỏ hàng → mở CartDrawer | F97: ✅ Positive | G97: **🟠 P1** | I97: 1. Mở Design Studio 2. Click icon ShoppingBag | J97: Mở CartDrawer slide-over từ bên phải. Hiển thị danh sách items hoặc empty state | L97: Add new | M97: By AI | N97: Manual | O97: Untested | T97: Untested
A98: TC_DS_002 | B98: DS - Sidebar | C98: US-DS-02 | D98: Sidebar | E98: Click 'Mặt Sau' chuyển view canvas | F98: ✅ Positive | G98: **🟠 P1** | I98: 1. Mở Design Studio 2. Click icon 'Mặt Sau' trên sidebar | J98: Canvas chuyển sang hiển thị mặt sau áo thun. Vùng thiết kế mặt sau hiển thị | L98: Add new | M98: By AI | N98: Manual | O98: Untested | T98: Untested
A99: TC_DS_003 | B99: DS - Sidebar | C99: US-DS-02 | D99: Sidebar | E99: Click 'Thử Đồ với AI' mở tính năng try-on | F99: ✅ Positive | G99: **🟠 P1** | I99: 1. Mở Design Studio 2. Click icon 'Thử Đồ với AI' | J99: Mở tính năng AI Try-on. Hiển thị form upload ảnh hoặc modal thử đồ | L99: Add new | M99: By AI | N99: Manual | O99: Untested | T99: Untested
...

Sheet AI GENERATE
A1: TC_ID | B1: Screen | C1: US_Mapping | D1: Module | E1: Title | F1: Type | G1: Priority | H1: Pre-condition | I1: Steps | J1: Expected Result | K1: Actual Result | L1: Action Type | M1: Create TCs Type | N1: Execution Type | O1: Result_R1 | P1: Test Date_R1 | Q1: Tester_R1 | R1: Bug ID_R1 | S1: Bug Desc_R1 | T1: Result_R2 | U1: Test Date_R2 | V1: Tester_R2 | W1: Bug ID_R2 | X1: Bug Desc_R2 | Y1: Evidence | Z1: Notes | AA1: Review_Manual (Feedback)
A2: 📌 UI/UX
A3: TC_AI_UI_013 | B3: DS - AI Panel | C3: US-37 | D3: AI Gen - UI/UX | E3: AI page: UI form cấu hình layout | F3: 🎨 UI/UX | G3: **🟠 P1** | I3: 1. Truy cập vào trang 2. Quan sát layout input form | J3: Input placeholder: 'Mô tả ý tưởng của bạn'. Styles: Digital Art, Realistic, Watercolor, Anime, Oil Painting. Thanh trượt 1-4 hình | L3: Add new | M3: By AI | N3: Manual | O3: Untested | T3: Untested
A4: TC_AI_UI_014 | B4: DS - AI Panel | C4: US-37 | D4: AI Gen - UI/UX | E4: AI page: Hiển thị chi phí generate | F4: 🎨 UI/UX | G4: **🟠 P1** | I4: 1. Truy cập vào trang 2. Thay đổi số lượng ảnh | J4: Hiển thị text: 'Tiêu tốn: X credits' (Vd: 'Tiêu tốn: 5 credits' khi generate 4 hình) | L4: Add new | M4: By AI | N4: Manual | O4: Untested | T4: Untested
A5: TC_DS_UI_006 | B5: DS - AI Panel | C5: US-DS-04 | D5: DS Chung - AI Panel | E5: AI Panel (bên phải) nội dung đầy đủ | F5: 🎨 UI/UX | G5: **🟠 P1** | I5: 1. Mở Design Studio 2. Trên AI Panel (mặc định hiển thị bên phải) 3. Quan sát nội dung panel | J5: Hiển thị: 'MÔ TẢ ARTWORK' (textarea), 'ẢNH THAM KHẢO' (2 nút: 'Chọn từ thư viện', 'Tải ảnh lên'), 'PHONG CÁCH' (6 style cards), text 'Mỗi lần tạo tốn 3 Credits', nút '✨ Tạo Artwork Mới' | L5: Add new | M5: By AI | N5: Manual | O5: Untested | T5: Untested
A6: TC_DS_UI_007 | B6: DS - AI Panel | C6: US-DS-04 | D6: DS Chung - AI Panel | E6: 6 phong cách AI có ảnh minh họa | F6: 🎨 UI/UX | G6: **🟠 P1** | I6: 1. Mở Design Studio 2. Trong AI Panel, quan sát phần PHONG CÁCH | J6: Hiển thị 6 style cards: 'Watercolor', 'Minimalist', 'Line Art', 'Retro', 'Grunge', 'Flat Design'. Mỗi card có ảnh minh họa + text tên style | L6: Add new | M6: By AI | N6: Manual | O6: Untested | T6: Untested
A7: TC_DS_UI_009 | B7: DS - AI Panel | C7: US-DS-04 | D7: DS Chung - AI Panel | E7: Textarea MÔ TẢ ARTWORK placeholder | F7: 🎨 UI/UX | G7: **🟢 P2** | I7: 1. Mở Design Studio 2. Quan sát textarea trong AI Panel | J7: Placeholder hiển thị: 'VD: Rồng Việt Nam phong cách watercolor, màu xanh lam và vàng...' | L7: Add new | M7: By AI | N7: Manual | O7: Untested | T7: Untested
A8: TC_CRD_UI_009 | B8: MH Credits | C8: US-40 | D8: Credits - UI/UX | E8: Wallet page: Header card số dư | F8: 🎨 UI/UX | G8: **🟠 P1** | I8: 1. Truy cập vào trang 2. Quan sát card số dư màu tím | J8: Hiển thị: 'Số dư hiện tại: [X] Credits'. Nút: 'Nạp thêm Credits', 'Rút Credits' | L8: Add new | M8: By AI | N8: Manual | O8: Untested | T8: Untested
A9: TC_CRD_UI_010 | B9: MH Credits | C9: US-41 | D9: Credits - UI/UX | E9: Wallet page: Lịch sử và Tabs | F9: 🎨 UI/UX | G9: **🟢 P2** | I9: 1. Truy cập vào trang 2. Quan sát bảng lịch sử giao dịch | J9: Có Tabs: 'Tất cả', 'Nhận', 'Sử dụng'. Bảng có: Ngày giao dịch, Loại, Nội dung, Số tiền (+/-), Số dư sau giao dịch. (vd: 'Chào mừng (+5)', 'Mua hàng (+10)') | L9: Add new | M9: By AI | N9: Manual | O9: Untested | T9: Untested
A10: TC_CRD_UI_011 | B10: MH Credits | C10: US-41 | D10: Credits - UI/UX | E10: Wallet page: Empty state | F10: 🎨 UI/UX | G10: **🟢 P2** | I10: 1. Truy cập vào trang 2. Mở trang Ví Credits | J10: Hiển thị empty state: 'Chưa có giao dịch credits nào' | L10: Add new | M10: By AI | N10: Manual | O10: Untested | T10: Untested
A11: 📌 Validation
A12: TC_AI_002 | B12: DS - AI Panel | C12: US-37 | D12: AI Gen - Engine | E12: Prompt rỗng | F12: ⚠️ Negative | G12: **🔴 P0** | I12: 1. Truy cập vào trang 2. Không nhập prompt 3. Click 'Generate' | J12: Validation: 'Vui lòng nhập mô tả' | L12: Add new | M12: By AI | N12: Manual | O12: Untested | T12: Untested
A13: TC_AI_003 | B13: DS - AI Panel | C13: US-37 | D13: AI Gen - Engine | E13: Prompt chứa nội dung nhạy cảm | F13: ⚠️ Negative | G13: **🔴 P0** | I13: 1. Truy cập vào trang 2. Nhập prompt vi phạm policy 3. Click 'Generate' | J13: Từ chối: 'Nội dung không phù hợp'. Không trừ credit | L13: Add new | M13: By AI | N13: Manual | O13: Untested | T13: Untested
A14: TC_AI_004 | B14: DS - AI Panel | C14: US-37 | D14: AI Gen - Engine | E14: Prompt rất dài (1000+ ký tự) | F14: ✅ Boundary | G14: **🟠 P1** | I14: 1. Truy cập vào trang 2. Nhập prompt 1000+ ký tự 3. Click 'Generate' | J14: Truncate hoặc warning max length | L14: Add new | M14: By AI | N14: Manual | O14: Untested | T14: Untested
A15: TC_AI_009 | B15: DS - AI Panel | C15: — | D15: AI Gen - Quota | E15: Guest: 2 lượt/ngày | F15: ⚠️ Negative | G15: **🔴 P0** | I15: 1. Truy cập vào trang 2. Click 'Generate' lần thứ 3 | J15: Hiển thị: 'Out of Credits'. Gợi ý đăng ký tài khoản | L15: Add new | M15: By AI | N15: Manual | O15: Untested | T15: Untested
A16: TC_AI_010 | B16: DS - AI Panel | C16: — | D16: AI Gen - Quota | E16: Free user: 10 lượt/ngày | F16: ⚠️ Negative | G16: **🔴 P0** | I16: 1. Truy cập vào trang 2. Click 'Generate' lần thứ 11 | J16: Hiển thị: 'Hết lượt tạo hôm nay'. Gợi ý chờ reset | L16: Add new | M16: By AI | N16: Manual | O16: Untested | T16: Untested
A17: TC_AI_011 | B17: DS - AI Panel | C17: — | D17: AI Gen - Quota | E17: Quota reset lúc 00:00 | F17: ✅ Boundary | G17: **🟠 P1** | I17: 1. Truy cập vào trang 2. Chờ qua 00:00 3. Thử Generate | J17: Quota reset. Generate thành công | L17: Add new | M17: By AI | N17: Manual | O17: Untested | T17: Untested
A18: TC_AI_007 | B18: DS - AI Panel | C18: US-38 | D18: AI Gen - Upscale | E18: Upscale khi hết credits | F18: ⚠️ Negative | G18: **🔴 P0** | I18: 1. Truy cập vào trang 2. Click 'Dùng ngay' | J18: Hiển thị: 'Hết credits'. Gợi ý chờ reset hoặc mua thêm | L18: Add new | M18: By AI | N18: Manual | O18: Untested | T18: Untested
A19: TC_DS_011 | B19: DS - AI Panel | C19: US-DS-04 | D19: DS Chung - AI Panel | E19: Nút 'Tạo Artwork Mới' disabled khi textarea MÔ TẢ rỗng | F19: ⚠️ Negative | G19: **🔴 P0** | I19: 1. Mở Design Studio 2. Không nhập gì vào textarea MÔ TẢ ARTWORK 3. Quan sát nút '✨ Tạo Artwork Mới' | J19: Nút '✨ Tạo Artwork Mới' bị disabled (mờ đi, không click được). Không trừ credits. Cursor không chuyển sang pointer khi hover | L19: Add new | M19: By AI | N19: Manual | O19: Untested | T19: Untested
A20: TC_DS_012 | B20: DS - AI Panel | C20: US-DS-04 | D20: DS Chung - AI Panel | E20: Tạo Artwork khi hết credits (0 credits) | F20: ⚠️ Negative | G20: **🔴 P0** | H20: Precondition: Tài khoản có 0 credits | I20: 1. Mở Design Studio 2. Nhập mô tả hợp lệ 3. Click '✨ Tạo Artwork Mới' | J20: Hiển thị: 'Hết credits'. Gợi ý nạp thêm. Không cho phép tạo artwork. Không trừ credits | L20: Add new | M20: By AI | N20: Manual | O20: Untested | T20: Untested
A21: TC_CRD_008 | B21: MH Credits | C21: US-42b | D21: Credits - Daily Reset | E21: Reset đúng theo timezone | F21: ✅ Boundary | G21: **🟠 P1** | I21: 1. Truy cập vào trang 2. Kiểm tra thời điểm reset | J21: Reset lúc 00:00 theo timezone server/user | L21: Add new | M21: By AI | N21: Manual | O21: Untested | T21: Untested
A22: TC_CRD_005 | B22: MH Credits | C22: US-42 | D22: Credits - Spend | E22: Dùng credits khi balance = 0 | F22: ⚠️ Negative | G22: **🔴 P0** | I22: 1. Truy cập vào trang 2. Thử Generate | J22: Hiển thị: 'Hết credits'. Không cho thực hiện | L22: Add new | M22: By AI | N22: Manual | O22: Untested | T22: Untested
A23: 📌 Functional
A24: TC_AI_001 | B24: DS - AI Panel | C24: US-37 | D24: AI Gen - Engine | E24: Nhập prompt → 4 preview ảnh | F24: ✅ Positive | G24: **🔴 P0** | I24: 1. Truy cập vào trang 2. Nhập prompt tiếng Việt 3. Chọn style: Digital Art 4. Click 'Generate' | J24: Loading state. Trả về 4 ảnh preview low-res trong 30-60s. Trừ 1 credit | L24: Add new | M24: By AI | N24: Manual | O24: Untested | T24: Untested
A25: TC_AI_005 | B25: DS - AI Panel | C25: US-37 | D25: AI Gen - Engine | E25: Generate khi đang generate (double click) | F25: ✅ Edge Case | G25: **🟠 P1** | I25: 1. Truy cập vào trang 2. Click 'Generate' 2 lần nhanh | J25: Chỉ 1 request được xử lý. Button disabled khi đang loading | L25: Add new | M25: By AI | N25: Manual | O25: Untested | T25: Untested
A26: TC_AI_008 | B26: DS - AI Panel | C26: US-39 | D26: AI Gen - UX | E26: Aha Moment messages khi render | F26: ✅ Positive | G26: **🟠 P1** | I26: 1. Truy cập vào trang 2. Quan sát loading state | J26: Messages xoay vui: 'Đang pha màu...', 'AI đang vẽ...' | L26: Add new | M26: By AI | N26: Manual | O26: Untested | T26: Untested
A27: TC_AI_006 | B27: DS - AI Panel | C27: US-38 | D27: AI Gen - Upscale | E27: Chọn 1 ảnh → upscale ≥2048px | F27: ✅ Positive | G27: **🔴 P0** | I27: 1. Truy cập vào trang 2. Click 'Dùng ngay' trên ảnh 1 | J27: Upscale 2k/4k. Lưu My Gallery. Chuyển sang Editor | L27: Add new | M27: By AI | N27: Manual | O27: Untested | T27: Untested
A28: TC_DS_032 | B28: DS - AI Panel | C28: US-DS-04 | D28: DS Chung - AI Panel | E28: Tạo Artwork thành công (happy path đầy đủ) | F28: ✅ Positive | G28: **🔴 P0** | I28: 1. Mở Design Studio → AI Panel (bên phải) 2. Nhập: 'Rồng Việt Nam phong cách watercolor' 3. Chọn style 'Watercolor' 4. Click '✨ Tạo Artwork Mới' | J28: Loading state hiển thị. Artwork mới xuất hiện trên canvas. Credits giảm 3 (từ 12 → 9) | L28: Add new | M28: By AI | N28: Manual | O28: Untested | T28: Untested
A29: TC_DS_006 | B29: DS - AI Panel | C29: US-DS-04 | D29: DS Chung - AI Panel | E29: Click style card để chọn phong cách AI | F29: ✅ Positive | G29: **🟠 P1** | I29: 1. Mở Design Studio → AI Panel (bên phải) 2. Click card 'Watercolor' 3. Click card 'Retro' | J29: Style card được chọn có highlight (border đậm hoặc background đổi). Style trước đó bỏ highlight | L29: Add new | M29: By AI | N29: Manual | O29: Untested | T29: Untested
A30: TC_DS_026 | B30: DS - AI Panel | C30: US-DS-04 | D30: DS Chung - AI Panel | E30: Click 'Chọn từ thư viện' trong ẢNH THAM KHẢO | F30: ✅ Positive | G30: **🟠 P1** | I30: 1. Mở Design Studio → AI Panel (bên phải) 2. Click nút 'Chọn từ thư viện' tại phần ẢNH THAM KHẢO | J30: Mở modal/gallery thư viện ảnh tham khảo. Cho phép chọn ảnh làm reference cho AI generate | L30: Add new | M30: By AI | N30: Manual | O30: Untested | T30: Untested
A31: TC_DS_027 | B31: DS - AI Panel | C31: US-DS-04 | D31: DS Chung - AI Panel | E31: Click 'Tải ảnh lên' trong ẢNH THAM KHẢO | F31: ✅ Positive | G31: **🟠 P1** | I31: 1. Mở Design Studio → AI Panel (bên phải) 2. Click nút 'Tải ảnh lên' tại phần ẢNH THAM KHẢO | J31: Mở native file picker (OS dialog). Chấp nhận file ảnh PNG/JPG. Ảnh upload hiển thị preview tại phần ẢNH THAM KHẢO | L31: Add new | M31: By AI | N31: Manual | O31: Untested | T31: Untested
A32: TC_DS_029 | B32: DS - AI Panel | C32: US-DS-04 | D32: DS Chung - AI Panel | E32: Click style card 'Line Art' chọn phong cách | F32: ✅ Positive | G32: **🟠 P1** | I32: 1. Mở Design Studio → AI Panel (bên phải) 2. Click card 'Line Art' | J32: Card 'Line Art' highlight (border đậm). Các card khác bỏ highlight | L32: Add new | M32: By AI | N32: Manual | O32: Untested | T32: Untested
A33: TC_DS_030 | B33: DS - AI Panel | C33: US-DS-04 | D33: DS Chung - AI Panel | E33: Click style card 'Grunge' chọn phong cách | F33: ✅ Positive | G33: **🟠 P1** | I33: 1. Mở Design Studio → AI Panel (bên phải) 2. Click card 'Grunge' | J33: Card 'Grunge' highlight. Các card khác bỏ highlight | L33: Add new | M33: By AI | N33: Manual | O33: Untested | T33: Untested
A34: TC_DS_031 | B34: DS - AI Panel | C34: US-DS-04 | D34: DS Chung - AI Panel | E34: Click style card 'Flat Design' chọn phong cách | F34: ✅ Positive | G34: **🟠 P1** | I34: 1. Mở Design Studio → AI Panel (bên phải) 2. Click card 'Flat Design' | J34: Card 'Flat Design' highlight. Các card khác bỏ highlight | L34: Add new | M34: By AI | N34: Manual | O34: Untested | T34: Untested
A35: TC_CRD_006 | B35: MH Credits | C35: US-42b | D35: Credits - Daily Reset | E35: Credits refill mỗi 24h | F35: ✅ Positive | G35: **🔴 P0** | I35: 1. Truy cập vào trang 2. Chờ qua 00:00 3. Kiểm tra balance | J35: Balance tự refill về mức mặc định (vd: 10 credits) | L35: Add new | M35: By AI | N35: Manual | O35: Untested | T35: Untested
... A40: TC_CRD_004 | B40: MH Credits | C40: US-42 | D40: Credits - Spend | E40: Dùng credits cho upscale | F40: ✅ Positive | G40: **🔴 P0** | I40: 1. Truy cập vào trang 2. Click 'Dùng ngay' (upscale) 3. Kiểm tra balance | J40: Trừ credits cho upscale | L40: Add new | M40: By AI | N40: Manual | O40: Untested | T40: Untested
A41: 📌 Security
A42: TC_DS_013 | B42: DS - AI Panel | C42: US-DS-04 | D42: DS Chung - AI Panel | E42: Nhập XSS vào textarea MÔ TẢ ARTWORK | F42: ⚠️ Negative | G42: **🟠 P1** | I42: 1. Mở Design Studio 2. Nhập '<script>alert(1)</script>' vào textarea 3. Click '✨ Tạo Artwork Mới' | J42: Hệ thống sanitize input. Không execute script. Prompt được escape đúng | L42: Add new | M42: By AI | N42: Manual | O42: Untested | T42: Untested
A43: 📌 Performance
A44: TC_AI_012 | B44: DS - AI Panel | C44: — | D44: AI Gen - Network | E44: Generate khi mất mạng giữa chừng | F44: ⚠️ Negative | G44: **🟠 P1** | I44: 1. Truy cập vào trang 2. Ngắt mạng giữa quá trình render | J44: Timeout message. Không trừ credit nếu chưa có kết quả | L44: Add new | M44: By AI | N44: Manual | O44: Untested | T44: Untested

Sheet ĐẶT HÀNG
A1: TC_ID | B1: Screen | C1: US_Mapping | D1: Module | E1: Title | F1: Type | G1: Priority | H1: Pre-condition | I1: Steps | J1: Expected Result | K1: Actual Result | L1: Action Type | M1: Create TCs Type | N1: Execution Type | O1: Result_R1 | P1: Test Date_R1 | Q1: Tester_R1 | R1: Bug ID_R1 | S1: Bug Desc_R1 | T1: Result_R2 | U1: Test Date_R2 | V1: Tester_R2 | W1: Bug ID_R2 | X1: Bug Desc_R2 | Y1: Evidence | Z1: Notes | AA1: Review_Manual (Feedback)
A2: 📌 UI/UX
A3: TC_CAR_UI_809 | B3: DS - OrderModal | C3: Global | D3: Responsive & Zoom | E3: Màn hình Cart: Browser Zoom In/Out (50% - 200%) giữ nguyên layout | F3: 🎨 UI/UX | G3: **🟠 P1** | I3: 1. Truy cập trang Cart. 2. Nhấn Ctrl/Cmd + [+] để Zoom In 200%. 3. Nhấn Ctrl/Cmd + [-] để Zoom Out 50%. 4. Cuộn và quan sát toàn màn hình. | J3: Text/SVG luôn sắc nét, không bị vỡ hạt (pixelated). Bố cục (Layout) thu phóng đúng tỷ lệ, không rớt dòng bậy bạ, không che lấp button quan trọng. | L3: Add new | M3: By AI | N3: Manual | O3: Untested | T3: Untested
A4: TC_CAR_UI_833 | B4: DS - OrderModal | C4: Global | D4: Responsive (Android Tablet) | E4: Màn hình Cart: Responsive trên Android Tablet (Chrome, Dọc - Portrait) | F4: 🎨 UI/UX | G4: **🟠 P1** | I4: 1. Truy cập trang Cart trên Tablet Android ở chế độ cầm dọc (Portrait). 2. Thao tác trên giao diện. | J4: Giao diện hoạt động trơn tru tương tự iPad, icon và text scale đúng chuẩn tỉ lệ (không quá bé hoặc quá khổng lồ). | L4: Add new | M4: By AI | N4: Manual | O4: Untested | T4: Untested
A5: TC_CAR_UI_831 | B5: DS - OrderModal | C5: Global | D5: Responsive (Android) | E5: Màn hình Cart: Responsive trên Android Phone (Chrome, Dọc - Portrait) | F5: 🎨 UI/UX | G5: **🔴 P0** | I5: 1. Truy cập trang Cart trên điện thoại Android chế độ cầm dọc (Portrait). 2. Cuộn lên/xuống toàn bộ trang. 3. Focus vào các input (bàn phím ảo hiện lên). | J5: Bố cục hoàn toàn responsive (tương tự iPhone). Đảm bảo thanh bar dưới cùng của trình duyệt Android hoặc bàn phím ảo không che khuất các nút CTA quan trọng. Màn hình không bị giật/nháy (flicker). | L5: Add new | M5: By AI | N5: Manual | O5: Untested | T5: Untested
A6: TC_CAR_UI_834 | B6: DS - OrderModal | C6: Global | D6: Responsive (Landscape) | E6: Màn hình Cart: Responsive chế độ Xoay Ngang (Landscape - Điện thoại/Tablet) | F6: 🎨 UI/UX | G6: **🔴 P0** | I6: 1. Từ trạng thái dọc, xoay ngang thiết bị di động (Landscape). 2. Đảm bảo tính năng xoay màn hình của hệ điều hành được bật. 3. Quan sát quá trình chuyển đổi giao diện. | J6: UI tự động sắp xếp lại chiều ngang phù hợp. Ở điện thoại, Sticky Footer/Header không chiếm quá nhiều không gian theo chiều dọc (để lại đủ không gian hiển thị nội dung). Không bị lủng layout trong lúc/sau khi xoay. | L6: Add new | M6: By AI | N6: Manual | O6: Untested | T6: Untested
A7: TC_CAR_UI_832 | B7: DS - OrderModal | C7: Global | D7: Responsive (iPad) | E7: Màn hình Cart: Responsive trên iPad (Safari, Dọc - Portrait) | F7: 🎨 UI/UX | G7: **🟠 P1** | I7: 1. Truy cập trang Cart trên iPad ở chế độ cầm dọc (Portrait). 2. Quan sát bố cục. | J7: Màn hình căn giữa hợp lý hoặc duy trì layout multi-column của Desktop nếu đủ không gian. Không bị rớt nút, không bị trải rộng (stretch) hình ảnh quá mức làm nhòa tỷ lệ. | L7: Add new | M7: By AI | N7: Manual | O7: Untested | T7: Untested
A8: TC_CAR_UI_830 | B8: DS - OrderModal | C8: Global | D8: Responsive (iPhone) | E8: Màn hình Cart: Responsive trên iPhone (Safari/Chrome, Dọc - Portrait) | F8: 🎨 UI/UX | G8: **🔴 P0** | I8: 1. Truy cập trang Cart trên iPhone ở chế độ cầm dọc (Portrait). 2. Cuộn lên/xuống toàn trang. 3. Tap thử các nút bấm, input field. | J8: Không xuất hiện thanh cuộn ngang thừa. Các khối nội dung hiển thị cột đơn (stacking). Các nút bấm (Touch Targets) không quá nhỏ, không nằm sát mép màn hình (có padding viền an toàn hợp lý). | L8: Add new | M8: By AI | N8: Manual | O8: Untested | T8: Untested
A9: TC_DSDH_UI_004 | B9: DS - OrderModal | C9: US-DS-05 | D9: Đặt hàng - Bottom Bar | E9: Nút 'Đặt hàng' style nổi bật | F9: 🎨 UI/UX | G9: **🟠 P1** | I9: 1. Mở Design Studio 2. Quan sát nút 'Đặt hàng' trên bottom bar | J9: Nút 'Đặt hàng' có background đậm, text trắng, bo tròn. Đủ lớn để click. Có hover effect | L9: Add new | M9: By AI | N9: Manual | O9: Untested | T9: Untested
A10: TC_DSDH_UI_001 | B10: DS - OrderModal | C10: US-DS-05 | D10: Đặt hàng - Panel | E10: OrderModal (popup từ StatusBar): Form đặt hàng hiển thị đầy đủ | F10: 🎨 UI/UX | G10: **🟠 P1** | I10: 1. Mở Design Studio 2. Click nút 'Đặt hàng' trên StatusBar → OrderModal 3. Quan sát panel | J10: Hiển thị form đặt hàng: thông tin sản phẩm (tên, màu, size), ảnh preview thiết kế, số lượng selector, tổng giá. Nút 'Đặt hàng' nổi bật | L10: Add new | M10: By AI | N10: Manual | O10: Untested | T10: Untested
A11: TC_DSDH_UI_002 | B11: DS - OrderModal | C11: US-DS-05 | D11: Đặt hàng - Panel | E11: Thông tin giá hiển thị rõ ràng | F11: 🎨 UI/UX | G11: **🟠 P1** | I11: 1. Mở DS → OrderModal (popup từ StatusBar) 2. Quan sát phần giá | J11: Hiển thị: Đơn giá, Số lượng, Phí in (nếu có), Tổng cộng. Font size tổng cộng lớn hơn, đậm hơn. Đơn vị tiền VNĐ rõ ràng | L11: Add new | M11: By AI | N11: Manual | O11: Untested | T11: Untested
A12: TC_DSDH_UI_003 | B12: DS - OrderModal | C12: US-DS-05 | D12: Đặt hàng - Panel | E12: Preview thiết kế trong form đặt hàng | F12: 🎨 UI/UX | G12: **🟠 P1** | I12: 1. Mở DS (có artwork trên canvas) → OrderModal (popup từ StatusBar) 2. Quan sát preview | J12: Hiển thị ảnh preview sản phẩm với thiết kế đã tạo. Preview rõ nét, tương ứng với canvas | L12: Add new | M12: By AI | N12: Manual | O12: Untested | T12: Untested
A13: TC_PRO_007 | B13: MH Chi tiết SP | C13: US-12 | D13: Sản phẩm - Size | E13: Size Chart responsive mobile | F13: 🎨 UI/UX | G13: **🟢 P2** | I13: 1. Truy cập vào trang 2. Mở bảng size trên mobile | J13: Bảng scroll ngang hoặc stack. Không bị cắt cột | L13: Add new | M13: By AI | N13: Manual | O13: Untested | T13: Untested
A14: TC_CART_UI_003 | B14: MH Giỏ hàng | C14: US-20 | D14: Giỏ hàng - Empty | E14: MH Giỏ hàng: Empty state khi giỏ trống | F14: 🎨 UI/UX | G14: **🟠 P1** | I14: 1. Mở MH Giỏ hàng (chưa thêm sản phẩm) 2. Quan sát nội dung | J14: Hiển thị empty state: icon giỏ hàng trống + text 'Giỏ hàng trống' + nút CTA 'Thiết kế ngay' hoặc 'Khám phá sản phẩm' | L14: Add new | M14: By AI | N14: Manual | O14: Untested | T14: Untested
... A22: TC_CART_UI_861 | B22: MH Giỏ hàng | C22: Global | D22: Responsive (iPhone) | E22: MH Giỏ hàng: Responsive iPhone (Portrait) | F22: 🎨 UI/UX | G22: **🔴 P0** | I22: 1. Truy cập MH Giỏ hàng trên iPhone Portrait 2. Thao tác với các items | J22: Không thanh cuộn ngang. Items hiển thị dạng card stacking. Nút xóa dễ tap. Touch targets ≥44px | L22: Add new | M22: By AI | N22: Manual | O22: Untested | T22: Untested
A23: 📌 Validation
A24: TC_DH_SC_011 | B24: DS - OrderModal | C24: US-DS-05 | D24: OrderTab - Discount | E24: <10 chiếc → KHÔNG giảm giá | F24: ⚠️ Negative | G24: **🟠 P1** | I24: 1. OrderModal 2. Thêm 5 chiếc | J24: Dòng 'Giảm SL' KHÔNG hiển thị. Tổng = giá gốc. discountPercent = 0 | L24: Add new | M24: By AI | N24: Manual | O24: Untested | T24: Untested
A25: TC_DH_SC_015 | B25: DS - OrderModal | C25: US-DS-05 | D25: OrderTab - Promo | E25: Mã sai → hiện 'Mã không hợp lệ hoặc đã hết hạn' | F25: ⚠️ Negative | G25: **🟠 P1** | I25: 1. OrderModal → Nhập mã 'INVALIDCODE' 2. Click 'Áp dụng' | J25: Hiển thị dòng đỏ: 'Mã không hợp lệ hoặc đã hết hạn'. Mã không được áp dụng | L25: Add new | M25: By AI | N25: Manual | O25: Untested | T25: Untested
A26: TC_DSDH_V_004 | B26: DS - OrderModal | C26: US-DS-05 | D26: Thanh toán | E26: Thanh toán thiếu thông tin bắt buộc | F26: ⚠️ Negative | G26: **🔴 P0** | I26: 1. Từ Mua ngay → Trang Thanh toán 2. Để trống các field bắt buộc (tên, địa chỉ, SĐT) 3. Click Xác nhận | J26: Hiển thị validation error cho từng field trống. Không tạo đơn hàng | L26: Add new | M26: By AI | N26: Manual | O26: Untested | T26: Untested
A27: TC_DSDH_V_001 | B27: DS - OrderModal | C27: US-DS-05 | D27: Đặt hàng - Panel | E27: Đặt hàng khi canvas trống (không có thiết kế) | F27: ⚠️ Negative | G27: **🔴 P0** | I27: 1. Mở DS (canvas trống, không có artwork) 2. Click 'Đặt hàng' | J27: Hiển thị thông báo: 'Vui lòng thêm thiết kế trước khi đặt hàng'. Không cho phép checkout với áo trống | L27: Add new | M27: By AI | N27: Manual | O27: Untested | T27: Untested
A28: TC_DSDH_V_002 | B28: DS - OrderModal | C28: US-DS-05 | D28: Đặt hàng - Panel | E28: Số lượng = 0 hoặc âm | F28: ⚠️ Negative | G28: **🟠 P1** | I28: 1. Mở DS → OrderModal (popup từ StatusBar) 2. Nhập số lượng = 0 hoặc -1 | J28: Không cho phép đặt với số lượng ≤ 0. Nút disabled hoặc hiển thị validation error. Số lượng tối thiểu = 1 | L28: Add new | M28: By AI | N28: Manual | O28: Untested | T28: Untested
A29: TC_DSDH_V_003 | B29: DS - OrderModal | C29: US-DS-05 | D29: Đặt hàng - Panel | E29: Số lượng vượt giới hạn tối đa | F29: ⚠️ Negative | G29: **🟢 P2** | I29: 1. Mở DS → OrderModal (popup từ StatusBar) 2. Nhập số lượng = 99999 | J29: Hiển thị giới hạn tối đa (ví dụ: 100). Không cho phép vượt. Thông báo 'Số lượng tối đa là X' | L29: Add new | M29: By AI | N29: Manual | O29: Untested | T29: Untested
A30: TC_PRO_005 | B30: MH Chi tiết SP | C30: US-11 | D30: Sản phẩm - Color | E30: Đổi màu nhiều lần liên tiếp | F30: ✅ Boundary | G30: **🟠 P1** | I30: 1. Truy cập vào trang 2. Click Navy 3. Click White 4. Click Red nhanh liên tục | J30: Mockup update mượt, không lag/flicker | L30: Add new | M30: By AI | N30: Manual | O30: Untested | T30: Untested
A31: TC_ORD_002 | B31: MH Giỏ hàng | C31: US-20 | D31: Giỏ hàng - Add | E31: Add với qty = 0 | F31: ⚠️ Negative | G31: **🟠 P1** | I31: 1. Truy cập vào trang 2. Nhập Qty: 0 3. Click 'Add to Cart' | J31: Validation: qty phải >= 1 | L31: Add new | M31: By AI | N31: Manual | O31: Untested | T31: Untested
A32: TC_CART_V_001 | B32: MH Giỏ hàng | C32: US-20 | D32: Giỏ hàng - Qty | E32: Cập nhật số lượng = 0 | F32: ⚠️ Negative | G32: **🟠 P1** | I32: 1. Mở Giỏ hàng 2. Giảm qty xuống 0 | J32: Hiển thị confirm xóa item hoặc tự động xóa. Qty tối thiểu = 1 | L32: Add new | M32: By AI | N32: Manual | O32: Untested | T32: Untested
A33: TC_CART_V_002 | B33: MH Giỏ hàng | C33: US-20 | D33: Giỏ hàng - Qty | E33: Nhập số lượng bằng chữ | F33: ⚠️ Negative | G33: **🟢 P2** | I33: 1. Mở Giỏ hàng 2. Nhập qty: 'abc' | J33: Input chỉ nhận số. Không crash | L33: Add new | M33: By AI | N33: Manual | O33: Untested | T33: Untested
A34: TC_CART_V_003 | B34: MH Giỏ hàng | C34: US-20 | D34: Giỏ hàng - Qty | E34: Số lượng vượt tối đa (>100) | F34: ⚠️ Negative | G34: **🟢 P2** | I34: 1. Mở Giỏ hàng 2. Nhập qty: 999 | J34: Giới hạn tối đa hoặc hiển thị warning | L34: Add new | M34: By AI | N34: Manual | O34: Untested | T34: Untested
A35: 📌 Functional
A36: TC_DH_SC_007 | B36: DS - OrderModal | C36: US-DS-05 | D36: OrderTab - Discount | E36: 10-29 chiếc → giảm 5% | F36: ✅ Positive | G36: **🟠 P1** | I36: 1. OrderModal 2. Thêm tổng 10+ chiếc (vd: S×5, M×5) | J36: Hiển thị dòng 'Giảm SL −5%' màu xanh. Số tiền giảm = 5% × subtotal. Source: {min:10, percent:5} | L36: Add new | M36: By AI | N36: Manual | O36: Untested | T36: Untested
A37: TC_DH_SC_008 | B37: DS - OrderModal | C37: US-DS-05 | D37: OrderTab - Discount | E37: 30-49 chiếc → giảm 10% | F37: ✅ Positive | G37: **🟠 P1** | I37: 1. OrderModal 2. Thêm tổng 30+ chiếc | J37: Hiển thị 'Giảm SL −10%'. Source: {min:30, percent:10} | L37: Add new | M37: By AI | N37: Manual | O37: Untested | T37: Untested
A38: TC_DH_SC_009 | B38: DS - OrderModal | C38: US-DS-05 | D38: OrderTab - Discount | E38: 50-99 chiếc → giảm 15% | F38: ✅ Positive | G38: **🟠 P1** | I38: 1. OrderModal 2. Thêm tổng 50+ chiếc | J38: Hiển thị 'Giảm SL −15%'. Source: {min:50, percent:15} | L38: Add new | M38: By AI | N38: Manual | O38: Untested | T38: Untested
A39: TC_DH_SC_010 | B39: DS - OrderModal | C39: US-DS-05 | D39: OrderTab - Discount | E39: 100+ chiếc → giảm 20% | F39: ✅ Positive | G39: **🟠 P1** | I39: 1. OrderModal 2. Thêm tổng 100+ chiếc | J39: Hiển thị 'Giảm SL −20%'. Source: {min:100, percent:20} | L39: Add new | M39: By AI | N39: Manual | O39: Untested | T39: Untested
A40: TC_DH_SC_001 | B40: DS - OrderModal | C40: US-DS-05 | D40: OrderTab - Pricing | E40: Giá sizes S/M/L = 120.000đ | F40: ✅ Positive | G40: **🔴 P0** | I40: 1. Mở DS → OrderModal 2. Chọn size S, M hoặc L | J40: Giá mỗi chiếc = 120.000đ. Hiển thị đúng trong bảng giá. Source: SIZE_PRICES = {S:120000, M:120000, L:120000} | L40: Add new | M40: By AI | N40: Manual | O40: Untested | T40: Untested
A41: TC_DH_SC_002 | B41: DS - OrderModal | C41: US-DS-05 | D41: OrderTab - Pricing | E41: Giá size XL = 130.000đ | F41: ✅ Positive | G41: **🔴 P0** | I41: 1. Mở DS → OrderModal 2. Chọn size XL | J41: Giá mỗi chiếc = 130.000đ. Chênh +10k so với S/M/L | L41: Add new | M41: By AI | N41: Manual | O41: Untested | T41: Untested
A42: TC_DH_SC_003 | B42: DS - OrderModal | C42: US-DS-05 | D42: OrderTab - Pricing | E42: Giá size 2XL = 140.000đ | F42: ✅ Positive | G42: **🔴 P0** | I42: 1. Mở DS → OrderModal 2. Chọn size 2XL | J42: Giá mỗi chiếc = 140.000đ. Chênh +20k so với S/M/L | L42: Add new | M42: By AI | N42: Manual | O42: Untested | T42: Untested
A43: TC_DH_SC_004 | B43: DS - OrderModal | C43: US-DS-05 | D43: OrderTab - Pricing | E43: Phí in DTG = 30.000đ/chiếc | F43: ✅ Positive | G43: **🟠 P1** | I43: 1. Có artwork trên canvas 2. Mở OrderModal, thêm size S ×1 | J43: Dòng 'Phí in DTG' hiển thị = 30.000đ × số chiếc. Source: PRINT_COST=30000 | L43: Add new | M43: By AI | N43: Manual | O43: Untested | T43: Untested
